<problem chapter='2' section='6' slide='1' problem='11' title="Hibák – a programozók mindennapi kenyere | try-except">

<!--
Update history:
2020-09-21 Grzegorz (review, PEP-8 compliance check, update, title correction)
-->

<code>
try:
    x = int(input("Enter a number: "))
    y = 1 / x
    print(y)
except ValueError:
    print("You must enter an integer value.")

print("THE END.")

</code>



<h1>Kivételek (folytatás)</h1>

<p>Rontsuk el még egyszer a kódot.</p>

<p>Nézd meg a programot a szerkesztőben. Ezúttal eltávolítottuk a névtelen ágat.</p>


<p>A felhasználó ismét beírja a <codel>0</codel>-t, és:</p>

<ul>
<li>a kivételt nem kezeli a <codel>ValueError</codel> – semmi köze hozzá;</li>

<li>
    mivel nincs másik ág, ezt az üzenetet kell látnod:
    <br><br>

    <codep>
        Traceback (most recent call last):
        File "exc.py", line 3, in <module>
            y = 1 / x
            ZeroDivisionError: division by zero
    </codep>
    <p style="text-align: right;"><font size="-2"><b>kimenet</b></font></p>
</li>
</ul>

<br>

<p>Sokat tanultál a Pythonban a kivételek kezeléséről. A következő részben a Python beépített kivételeivel és azok hierarchiájával foglalkozunk.</p>

<br>
<br>

<studyMode>false</studyMode>
<labMode>false</labMode>

</problem>
